Workbook

Sheet Backtesting v4.0
A1: BACKTESTING DETALLADO - BOT v4.0
A2: Fecha: 2026-04-09
A4: INSTRUCCIONES:
A5: 1. Completa cada fila con UN TRADE que tu bot habría abierto
A6: 2. Usa TradingView Replay para simular en tiempo real
A7: 3. Registra: Tier, Entry, SL, TP1, TP2, MFI, ZLSMA, ADX, Precio de salida
A8: 4. Resultado = (Salida - Entry) / (Entry - SL) en unidades R
A9: 5. Las métricas se calculan automáticamente abajo
A10: 6. Target: Win Rate ≥65%, Expectancy ≥+0.5R
A12: Fecha | B12: Hora | C12: Par | D12: Tier | E12: Direction | F12: Entry | G12: SL | H12: TP1 | I12: TP2 | J12: MFI | K12: ZLSMA % | L12: ADX | M12: Salida Real | N12: Resultado (R) | O12: Win | P12: Notas
A13: 2024-01-15 | B13: 15:45 | C13: BTC-USDT | D13: A | E13: LONG | F13: 42500 | G13: 42350 | H13: 42650 | I13: 42800 | J13: 35 | K13: +0.8 | L13: 28 | M13: 42750 | N13: =IF(D13="LONG",(M13-F13)/(F13-G13),(H13-M13)/(H13-G13)) | O13: =IF(N13>0,1,0) | P13: Clean entry on ZLSMA bounce
N14: =IF(AND(F14<>"",G14<>"",M14<>""),IF(D14="LONG",(M14-F14)/(F14-G14),(H14-M14)/(H14-G14)),"") | O14: =IF(N14>0,1,IF(N14<0,0,""))
N15: =IF(AND(F15<>"",G15<>"",M15<>""),IF(D15="LONG",(M15-F15)/(F15-G15),(H15-M15)/(H15-G15)),"") | O15: =IF(N15>0,1,IF(N15<0,0,""))
N16: =IF(AND(F16<>"",G16<>"",M16<>""),IF(D16="LONG",(M16-F16)/(F16-G16),(H16-M16)/(H16-G16)),"") | O16: =IF(N16>0,1,IF(N16<0,0,""))
N17: =IF(AND(F17<>"",G17<>"",M17<>""),IF(D17="LONG",(M17-F17)/(F17-G17),(H17-M17)/(H17-G17)),"") | O17: =IF(N17>0,1,IF(N17<0,0,""))
N18: =IF(AND(F18<>"",G18<>"",M18<>""),IF(D18="LONG",(M18-F18)/(F18-G18),(H18-M18)/(H18-G18)),"") | O18: =IF(N18>0,1,IF(N18<0,0,""))
N19: =IF(AND(F19<>"",G19<>"",M19<>""),IF(D19="LONG",(M19-F19)/(F19-G19),(H19-M19)/(H19-G19)),"") | O19: =IF(N19>0,1,IF(N19<0,0,""))
N20: =IF(AND(F20<>"",G20<>"",M20<>""),IF(D20="LONG",(M20-F20)/(F20-G20),(H20-M20)/(H20-G20)),"") | O20: =IF(N20>0,1,IF(N20<0,0,""))
N21: =IF(AND(F21<>"",G21<>"",M21<>""),IF(D21="LONG",(M21-F21)/(F21-G21),(H21-M21)/(H21-G21)),"") | O21: =IF(N21>0,1,IF(N21<0,0,""))
N22: =IF(AND(F22<>"",G22<>"",M22<>""),IF(D22="LONG",(M22-F22)/(F22-G22),(H22-M22)/(H22-G22)),"") | O22: =IF(N22>0,1,IF(N22<0,0,""))
N23: =IF(AND(F23<>"",G23<>"",M23<>""),IF(D23="LONG",(M23-F23)/(F23-G23),(H23-M23)/(H23-G23)),"") | O23: =IF(N23>0,1,IF(N23<0,0,""))
N24: =IF(AND(F24<>"",G24<>"",M24<>""),IF(D24="LONG",(M24-F24)/(F24-G24),(H24-M24)/(H24-G24)),"") | O24: =IF(N24>0,1,IF(N24<0,0,""))
N25: =IF(AND(F25<>"",G25<>"",M25<>""),IF(D25="LONG",(M25-F25)/(F25-G25),(H25-M25)/(H25-G25)),"") | O25: =IF(N25>0,1,IF(N25<0,0,""))
... N113: =IF(AND(F113<>"",G113<>"",M113<>""),IF(D113="LONG",(M113-F113)/(F113-G113),(H113-M113)/(H113-G113)),"") | O113: =IF(N113>0,1,IF(N113<0,0,""))
A116: MÉTRICAS CALCULADAS
A118: Trades Ganados | C118: =COUNTIF(O14:O113,1)
A119: Trades Perdidos | C119: =COUNTIF(O14:O113,0)
A120: Tier S Win % | C120: =IF(E120=0,0,(SUMIFS(O14:O113,D14:D113,"S")/E120)*100)
A121: Tier A Win % | C121: =IF(F121=0,0,(SUMIFS(O14:O113,D14:D113,"A")/F121)*100)
A122: Promedio R Perdedores | C122: =IF(COUNTIF(O14:O113,0)=0,0,ABS(AVERAGEIF(O14:O113,"<0",N14:N113)))
A123: Net R | C123: =H123-I123
A124: Max Drawdown | C124: =(ver nota abajo)
A127: INTERPRETACIÓN DE MÉTRICAS
A128: ✅ Win Rate ≥65%: Bueno | ≥72%: Excelente | <60%: Revisar estrategia
A129: ✅ Tier S Win % ≥75%: Filtro está funcionando bien
A130: ✅ Tier A Win % ≥65%: Aceptable
A131: ✅ Profit Factor ≥2.0: Excelente | 1.5-2.0: Bueno | <1.5: Revisar
A132: ✅ Expectancy ≥+0.5R: Rentable | ≥+1.0R: Muy rentable
A133: ✅ Max Drawdown <15%: Aceptable | <10%: Bueno (cuenta pérdidas consecutivas)
A135: FÓRMULA DE EXPECTANCY:
...

Sheet Resumen por Tier
A1: ANÁLISIS DETALLADO POR TIER
A3: Tier | B3: Total Trades | C3: Ganados | D3: Perdidos | E3: Win % | F3: Avg R
A4: S | B4: =COUNTIF(Backtesting!D14:D113,"S") | C4: =SUMIFS(Backtesting!O14:O113,Backtesting!D14:D113,"S") | D4: =B4-C4 | E4: =IF(B4=0,0,(C4/B4)*100) | F4: =AVERAGEIFS(Backtesting!N14:N113,Backtesting!D14:D113,"S")
A5: A | B5: =COUNTIF(Backtesting!D14:D113,"A") | C5: =SUMIFS(Backtesting!O14:O113,Backtesting!D14:D113,"A") | D5: =B5-C5 | E5: =IF(B5=0,0,(C5/B5)*100) | F5: =AVERAGEIFS(Backtesting!N14:N113,Backtesting!D14:D113,"A")
A6: B | B6: =COUNTIF(Backtesting!D14:D113,"B") | C6: =SUMIFS(Backtesting!O14:O113,Backtesting!D14:D113,"B") | D6: =B6-C6 | E6: =IF(B6=0,0,(C6/B6)*100) | F6: =AVERAGEIFS(Backtesting!N14:N113,Backtesting!D14:D113,"B")
